2025-03-05 14:10:22 | ERROR | (1305, 'PROCEDURE risk_db.sp_verifyIdentity does not exist')
2025-03-05 14:10:22 | ERROR | Traceback (most recent call last):
  File "/app/src/routes/AuthRoutes.py", line 24, in login
    authenticated_user = AuthService.login_user(_user)
  File "/app/src/services/AuthService.py", line 17, in login_user
    cursor.execute('call sp_verifyIdentity(%s, %s)', (user.username, user.password))
  File "/usr/local/lib/python3.10/site-packages/pymysql/cursors.py", line 153, in execute
    result = self._query(query)
  File "/usr/local/lib/python3.10/site-packages/pymysql/cursors.py", line 322, in _query
    conn.query(q)
  File "/usr/local/lib/python3.10/site-packages/pymysql/connections.py", line 563, in query
    self._affected_rows = self._read_query_result(unbuffered=unbuffered)
  File "/usr/local/lib/python3.10/site-packages/pymysql/connections.py", line 825, in _read_query_result
    result.read()
  File "/usr/local/lib/python3.10/site-packages/pymysql/connections.py", line 1199, in read
    first_packet = self.connection._read_packet()
  File "/usr/local/lib/python3.10/site-packages/pymysql/connections.py", line 775, in _read_packet
    packet.raise_for_error()
  File "/usr/local/lib/python3.10/site-packages/pymysql/protocol.py", line 219, in raise_for_error
    err.raise_mysql_exception(self._data)
  File "/usr/local/lib/python3.10/site-packages/pymysql/err.py", line 150, in raise_mysql_exception
    raise errorclass(errno, errval)
pymysql.err.OperationalError: (1305, 'PROCEDURE risk_db.sp_verifyIdentity does not exist')

2025-03-05 14:14:35 | ERROR | 'username'
2025-03-05 14:14:35 | ERROR | Traceback (most recent call last):
  File "/app/src/routes/AuthRoutes.py", line 20, in login
    username = request.json['username']
KeyError: 'username'

