2025-03-07 02:25:59 | INFO | Received data: 
2025-03-07 02:27:41 | INFO | Received data: {'title': 'RISK001', 'description': 'RISK001', 'cod': 'RISK001', 'impact': '', 'resolved': False}
2025-03-07 02:27:41 | ERROR | (1062, "Duplicate entry 'RISK001' for key 'risks.cod'")
2025-03-07 02:27:41 | ERROR | Traceback (most recent call last):
  File "/app/src/services/RiskService.py", line 100, in add_risk
    cursor.callproc(
  File "/usr/local/lib/python3.10/site-packages/pymysql/cursors.py", line 269, in callproc
    self._query(q)
  File "/usr/local/lib/python3.10/site-packages/pymysql/cursors.py", line 322, in _query
    conn.query(q)
  File "/usr/local/lib/python3.10/site-packages/pymysql/connections.py", line 563, in query
    self._affected_rows = self._read_query_result(unbuffered=unbuffered)
  File "/usr/local/lib/python3.10/site-packages/pymysql/connections.py", line 825, in _read_query_result
    result.read()
  File "/usr/local/lib/python3.10/site-packages/pymysql/connections.py", line 1199, in read
    first_packet = self.connection._read_packet()
  File "/usr/local/lib/python3.10/site-packages/pymysql/connections.py", line 775, in _read_packet
    packet.raise_for_error()
  File "/usr/local/lib/python3.10/site-packages/pymysql/protocol.py", line 219, in raise_for_error
    err.raise_mysql_exception(self._data)
  File "/usr/local/lib/python3.10/site-packages/pymysql/err.py", line 150, in raise_mysql_exception
    raise errorclass(errno, errval)
pymysql.err.IntegrityError: (1062, "Duplicate entry 'RISK001' for key 'risks.cod'")

2025-03-07 02:27:41 | ERROR | not enough values to unpack (expected 2, got 0)
2025-03-07 02:27:41 | ERROR | Traceback (most recent call last):
  File "/app/src/routes/RiskRoutes.py", line 91, in add_risks
    success, message = RiskService.add_risk(risk_data)
ValueError: not enough values to unpack (expected 2, got 0)

2025-03-07 02:27:59 | INFO | Received data: {'title': 'RISK001', 'description': 'RISK001', 'cod': 'RISK0101', 'impact': '', 'resolved': False}
2025-03-07 12:04:21 | INFO | Received data: {'title': 'sdadsad', 'description': 'asdsdasd', 'cod': 'RISK123', 'impact': '', 'resolved': True}
2025-03-07 12:07:36 | INFO | Received data: {'title': 'sdadsad', 'description': 'asdsdasd', 'cod': 'RISK123', 'impact': '', 'resolved': True}
2025-03-07 12:07:36 | ERROR | (1062, "Duplicate entry 'RISK123' for key 'risks.cod'")
2025-03-07 12:07:36 | ERROR | Traceback (most recent call last):
  File "/app/src/services/RiskService.py", line 99, in add_risk
    cursor.callproc(
  File "/usr/local/lib/python3.10/site-packages/pymysql/cursors.py", line 269, in callproc
    self._query(q)
  File "/usr/local/lib/python3.10/site-packages/pymysql/cursors.py", line 322, in _query
    conn.query(q)
  File "/usr/local/lib/python3.10/site-packages/pymysql/connections.py", line 563, in query
    self._affected_rows = self._read_query_result(unbuffered=unbuffered)
  File "/usr/local/lib/python3.10/site-packages/pymysql/connections.py", line 825, in _read_query_result
    result.read()
  File "/usr/local/lib/python3.10/site-packages/pymysql/connections.py", line 1199, in read
    first_packet = self.connection._read_packet()
  File "/usr/local/lib/python3.10/site-packages/pymysql/connections.py", line 775, in _read_packet
    packet.raise_for_error()
  File "/usr/local/lib/python3.10/site-packages/pymysql/protocol.py", line 219, in raise_for_error
    err.raise_mysql_exception(self._data)
  File "/usr/local/lib/python3.10/site-packages/pymysql/err.py", line 150, in raise_mysql_exception
    raise errorclass(errno, errval)
pymysql.err.IntegrityError: (1062, "Duplicate entry 'RISK123' for key 'risks.cod'")

2025-03-07 12:07:57 | INFO | Received data: {'title': 'sdadsad', 'description': 'asdsdasd', 'cod': 'RISK124', 'impact': '', 'resolved': True}
2025-03-07 12:09:12 | INFO | Received data: {'title': 'sdadsad', 'description': 'asdsdasd', 'cod': 'RISK125', 'impact': '', 'resolved': True}
2025-03-07 12:09:23 | INFO | Received data: {'title': 'sdadsad', 'description': 'asdsdasd', 'cod': 'RISK126', 'impact': '', 'resolved': True}
2025-03-07 12:10:01 | INFO | Received data: {'title': 'Franco', 'description': 'sdadsad', 'cod': 'RISK127', 'impact': 'High', 'resolved': False}
2025-03-07 13:05:10 | ERROR | All fields (username, password, fullname) are required.
2025-03-07 13:05:10 | ERROR | Traceback (most recent call last):
  File "/app/src/services/AuthService.py", line 27, in add_user
    raise CustomException("All fields (username, password, fullname) are required.")
src.utils.errors.CustomException.CustomException: All fields (username, password, fullname) are required.

During handling of the above exception, another exception occurred:

Traceback (most recent call last):
  File "/app/src/routes/AuthRoutes.py", line 47, in logUp
    response = AuthService.add_user(_user)
  File "/app/src/services/AuthService.py", line 38, in add_user
    raise CustomException(ex)
src.utils.errors.CustomException.CustomException: All fields (username, password, fullname) are required.

2025-03-07 13:05:20 | ERROR | An error occurred: (1062, "Duplicate entry 'Fran' for key 'user.username'")
2025-03-07 13:05:20 | ERROR | Traceback (most recent call last):
  File "/app/src/services/AuthService.py", line 32, in add_user
    cursor.execute('call sp_addUser(%s, %s, %s)', (user.username, user.password, user.fullname))
  File "/usr/local/lib/python3.10/site-packages/pymysql/cursors.py", line 153, in execute
    result = self._query(query)
  File "/usr/local/lib/python3.10/site-packages/pymysql/cursors.py", line 322, in _query
    conn.query(q)
  File "/usr/local/lib/python3.10/site-packages/pymysql/connections.py", line 563, in query
    self._affected_rows = self._read_query_result(unbuffered=unbuffered)
  File "/usr/local/lib/python3.10/site-packages/pymysql/connections.py", line 825, in _read_query_result
    result.read()
  File "/usr/local/lib/python3.10/site-packages/pymysql/connections.py", line 1199, in read
    first_packet = self.connection._read_packet()
  File "/usr/local/lib/python3.10/site-packages/pymysql/connections.py", line 775, in _read_packet
    packet.raise_for_error()
  File "/usr/local/lib/python3.10/site-packages/pymysql/protocol.py", line 219, in raise_for_error
    err.raise_mysql_exception(self._data)
  File "/usr/local/lib/python3.10/site-packages/pymysql/err.py", line 150, in raise_mysql_exception
    raise errorclass(errno, errval)
pymysql.err.IntegrityError: (1062, "Duplicate entry 'Fran' for key 'user.username'")

During handling of the above exception, another exception occurred:

Traceback (most recent call last):
  File "/app/src/routes/AuthRoutes.py", line 47, in logUp
    response = AuthService.add_user(_user)
  File "/app/src/services/AuthService.py", line 40, in add_user
    raise CustomException(f"An error occurred: {str(ex)}")
src.utils.errors.CustomException.CustomException: An error occurred: (1062, "Duplicate entry 'Fran' for key 'user.username'")

2025-03-07 13:05:25 | ERROR | All fields (username, password, fullname) are required.
2025-03-07 13:05:25 | ERROR | Traceback (most recent call last):
  File "/app/src/services/AuthService.py", line 27, in add_user
    raise CustomException("All fields (username, password, fullname) are required.")
src.utils.errors.CustomException.CustomException: All fields (username, password, fullname) are required.

During handling of the above exception, another exception occurred:

Traceback (most recent call last):
  File "/app/src/routes/AuthRoutes.py", line 47, in logUp
    response = AuthService.add_user(_user)
  File "/app/src/services/AuthService.py", line 38, in add_user
    raise CustomException(ex)
src.utils.errors.CustomException.CustomException: All fields (username, password, fullname) are required.

