2025-03-07 15:06:46 | ERROR | 'cryptography' package is required for sha256_password or caching_sha2_password auth methods
2025-03-07 15:06:46 | ERROR | Traceback (most recent call last):
  File "/app/src/database/db_mysql.py", line 9, in get_connection
    return pymysql.connect(
  File "/usr/local/lib/python3.10/site-packages/pymysql/connections.py", line 361, in __init__
    self.connect()
  File "/usr/local/lib/python3.10/site-packages/pymysql/connections.py", line 669, in connect
    self._request_authentication()
  File "/usr/local/lib/python3.10/site-packages/pymysql/connections.py", line 979, in _request_authentication
    auth_packet = _auth.caching_sha2_password_auth(self, auth_packet)
  File "/usr/local/lib/python3.10/site-packages/pymysql/_auth.py", line 267, in caching_sha2_password_auth
    data = sha2_rsa_encrypt(conn.password, conn.salt, conn.server_public_key)
  File "/usr/local/lib/python3.10/site-packages/pymysql/_auth.py", line 144, in sha2_rsa_encrypt
    raise RuntimeError(
RuntimeError: 'cryptography' package is required for sha256_password or caching_sha2_password auth methods

2025-03-07 15:06:46 | ERROR | An error occurred: 'NoneType' object has no attribute 'cursor'
2025-03-07 15:06:46 | ERROR | Traceback (most recent call last):
  File "/app/src/services/AuthService.py", line 32, in add_user
    with connection.cursor() as cursor:
AttributeError: 'NoneType' object has no attribute 'cursor'

During handling of the above exception, another exception occurred:

Traceback (most recent call last):
  File "/app/src/routes/AuthRoutes.py", line 44, in logUp
    response = AuthService.add_user(_user)
  File "/app/src/services/AuthService.py", line 41, in add_user
    raise CustomException(f"An error occurred: {str(ex)}")
src.utils.errors.CustomException.CustomException: An error occurred: 'NoneType' object has no attribute 'cursor'

2025-03-07 15:11:47 | ERROR | 'cryptography' package is required for sha256_password or caching_sha2_password auth methods
2025-03-07 15:11:47 | ERROR | Traceback (most recent call last):
  File "/app/src/database/db_mysql.py", line 9, in get_connection
    return pymysql.connect(
  File "/usr/local/lib/python3.10/site-packages/pymysql/connections.py", line 361, in __init__
    self.connect()
  File "/usr/local/lib/python3.10/site-packages/pymysql/connections.py", line 669, in connect
    self._request_authentication()
  File "/usr/local/lib/python3.10/site-packages/pymysql/connections.py", line 979, in _request_authentication
    auth_packet = _auth.caching_sha2_password_auth(self, auth_packet)
  File "/usr/local/lib/python3.10/site-packages/pymysql/_auth.py", line 267, in caching_sha2_password_auth
    data = sha2_rsa_encrypt(conn.password, conn.salt, conn.server_public_key)
  File "/usr/local/lib/python3.10/site-packages/pymysql/_auth.py", line 144, in sha2_rsa_encrypt
    raise RuntimeError(
RuntimeError: 'cryptography' package is required for sha256_password or caching_sha2_password auth methods

2025-03-07 15:11:47 | ERROR | 'NoneType' object has no attribute 'cursor'
2025-03-07 15:11:47 | ERROR | Traceback (most recent call last):
  File "/app/src/routes/AuthRoutes.py", line 21, in login
    authenticated_user = AuthService.login_user(_user)
  File "/app/src/services/AuthService.py", line 13, in login_user
    with connection.cursor() as cursor:
AttributeError: 'NoneType' object has no attribute 'cursor'

2025-03-07 15:14:28 | ERROR | 'cryptography' package is required for sha256_password or caching_sha2_password auth methods
2025-03-07 15:14:28 | ERROR | Traceback (most recent call last):
  File "/app/src/database/db_mysql.py", line 9, in get_connection
    return pymysql.connect(
  File "/usr/local/lib/python3.10/site-packages/pymysql/connections.py", line 361, in __init__
    self.connect()
  File "/usr/local/lib/python3.10/site-packages/pymysql/connections.py", line 669, in connect
    self._request_authentication()
  File "/usr/local/lib/python3.10/site-packages/pymysql/connections.py", line 979, in _request_authentication
    auth_packet = _auth.caching_sha2_password_auth(self, auth_packet)
  File "/usr/local/lib/python3.10/site-packages/pymysql/_auth.py", line 267, in caching_sha2_password_auth
    data = sha2_rsa_encrypt(conn.password, conn.salt, conn.server_public_key)
  File "/usr/local/lib/python3.10/site-packages/pymysql/_auth.py", line 144, in sha2_rsa_encrypt
    raise RuntimeError(
RuntimeError: 'cryptography' package is required for sha256_password or caching_sha2_password auth methods

2025-03-07 15:14:28 | ERROR | 'NoneType' object has no attribute 'cursor'
2025-03-07 15:14:28 | ERROR | Traceback (most recent call last):
  File "/app/src/routes/AuthRoutes.py", line 21, in login
    authenticated_user = AuthService.login_user(_user)
  File "/app/src/services/AuthService.py", line 13, in login_user
    with connection.cursor() as cursor:
AttributeError: 'NoneType' object has no attribute 'cursor'

2025-03-07 15:14:30 | ERROR | 'cryptography' package is required for sha256_password or caching_sha2_password auth methods
2025-03-07 15:14:30 | ERROR | Traceback (most recent call last):
  File "/app/src/database/db_mysql.py", line 9, in get_connection
    return pymysql.connect(
  File "/usr/local/lib/python3.10/site-packages/pymysql/connections.py", line 361, in __init__
    self.connect()
  File "/usr/local/lib/python3.10/site-packages/pymysql/connections.py", line 669, in connect
    self._request_authentication()
  File "/usr/local/lib/python3.10/site-packages/pymysql/connections.py", line 979, in _request_authentication
    auth_packet = _auth.caching_sha2_password_auth(self, auth_packet)
  File "/usr/local/lib/python3.10/site-packages/pymysql/_auth.py", line 267, in caching_sha2_password_auth
    data = sha2_rsa_encrypt(conn.password, conn.salt, conn.server_public_key)
  File "/usr/local/lib/python3.10/site-packages/pymysql/_auth.py", line 144, in sha2_rsa_encrypt
    raise RuntimeError(
RuntimeError: 'cryptography' package is required for sha256_password or caching_sha2_password auth methods

2025-03-07 15:14:30 | ERROR | 'NoneType' object has no attribute 'cursor'
2025-03-07 15:14:30 | ERROR | Traceback (most recent call last):
  File "/app/src/routes/AuthRoutes.py", line 21, in login
    authenticated_user = AuthService.login_user(_user)
  File "/app/src/services/AuthService.py", line 13, in login_user
    with connection.cursor() as cursor:
AttributeError: 'NoneType' object has no attribute 'cursor'

2025-03-07 15:17:03 | INFO | Received data: {'title': 'sadasd', 'description': 'adasds', 'cod': 'asdas', 'impact': 'High', 'resolved': False}
